Workbook

Sheet Input
A1: Proiezione pensionistica — Parametri di input
A2: Modifica le celle in BLU per personalizzare. Le formule (nero) si aggiornano automaticamente. Tutti gli importi sono in euro di oggi (valori reali).
A4: ANAGRAFICA E PROFILO
A5: Età corrente | B5: 45 | C5: anni
A6: Età target pensionamento | B6: 67 | C6: anni (range 57-71)
A7: Sesso | B7: M | C7: M / F
A9: LAVORO E REDDITO
A10: RAL lorda attuale | B10: 45000 | C10: €/anno
A11: Anzianità INPS corrente | B11: 18 | C11: anni
A12: Crescita RAL reale annua | B12: 0.015 | C12: es. 1,5% = 0,015
A13: Aliquota contribuzione dipendente | B13: 0.33 | C13: fissa: 33% per lavoro dipendente
A14: Montante INPS da estratto conto | B14: 0 | C14: € ad oggi dal sito INPS; 0 = usa la stima
A15: MACROECONOMIA
A16: Rivalutazione PIL reale annua (montante INPS) | B16: 0.005 | C16: PIL nominale per legge, meno l'inflazione: ~0,5% (come proiezione-inps.py)
A17: Inflazione attesa | B17: 0.02 | C17: target BCE 2%; serve al TFR in azienda, alla tassa del fondo in uscita e alla riga 21 degli Scenari
A18: Decadimento coefficiente / biennio | B18: 0.018 | C18: calo storico ~1,8% per biennio; 0 = congelato
A20: TFR
A21: TFR conferito a fondo (1=sì, 0=no) | B21: 1 | C21: 1 = conferito; 0 = in azienda
A22: Saldo TFR già accumulato | B22: 8000 | C22: € ad oggi (in azienda o conferito)
A24: FONDO PENSIONE COMPLEMENTARE
A25: Montante fondo accumulato (escluso TFR) | B25: 5000 | C25: € ad oggi
A26: Contributo volontario annuo | B26: 2000 | C26: €/anno; deduce nello spazio lasciato da datore e contributo dovuto (plafond B44)
A27: Contributo datore (% RAL) | B27: 0.015 | C27: es. 1,5% per CCNL metalmeccanici
A28: Rendimento netto reale comparto | B28: 0.025 | C28: al netto di costi, tassa del 20% e inflazione: bilanciato ~2,5% reale (come montecarlo-pensione.py)
A29: Anni di partecipazione correnti | B29: 5 | C29: per calcolo aliquota finale 15→9%
A31: SPESE E OBIETTIVI
A32: Spesa mensile attuale | B32: 2500 | C32: €/mese
A33: Fattore riduzione spesa post-pensione | B33: 0.78 | C33: tipico 0,75-0,85
A35: VALORI DERIVATI (formule)
A36: Anni residui al pensionamento | B36: =Input!$B$6-Input!$B$5 -> 22 | C36: calcolato
A37: Aliquota IRPEF marginale stimata | B37: =IF(Input!$B$10<=28000, 0.23, IF(Input!$B$10<=50000, 0.33, 0.43)) -> 0.33 | C37: scaglioni 2026
A38: Aliquota fondo finale al pensionamento | B38: =MAX(0.09, 0.15 - 0.003 * MAX(0, (Input!$B$29+Input!$B$36) - 15)) -> 0.114 | C38: 15% → 9% (-0,30%/anno dopo il 15°)
A39: Spesa annua target (valori reali) | B39: =Input!$B$32*12*Input!$B$33 -> 23400 | C39: spesa mensile × 12 × fattore
A40: Coefficiente proiettato al pensionamento | B40: =VLOOKUP(Input!$B$6, Coefficienti!A5:C19, 3, FALSE())*(1-Input!$B$18)^(Input!$B$36/2) -> 0.045923436 | C40: coeff. attuale ridotto per i bienni mancanti
A42: PARAMETRI NORMATIVI 2026
A43: Massimale contributivo annuo | B43: 122295 | C43: Circ. INPS 6/2026; oltre non si versano contributi (iscritti dal 1996)
A44: Plafond deducibilità fondo pensione | B44: 5300 | C44: art. 8 c. 4 D.Lgs. 252/2005: lavoratore + datore, TFR escluso
A46: FONDO PENSIONE E TFR — DETTAGLI
A47: Contributo dovuto lavoratore (% RAL) | B47: 0 | C47: minimo da CCNL per avere il contributo del datore (es. 1%); 0 se già nel volontario
A48: Anni di servizio già maturati (TFR) | B48: 3 | C48: per la tassazione separata del TFR in azienda (reddito di riferimento)
...

Sheet Coefficienti
A1: Coefficienti di trasformazione — biennio 2025-2026
A2: Fonte: Decreto direttoriale del 20 novembre 2024 (Min. Lavoro / MEF) — GU n. 35 del 12/02/2025
A4: Età | B4: Divisore | C4: Coefficiente
A5: 57 | B5: 23.789 | C5: 0.04204
A6: 58 | B6: 23.213 | C6: 0.04308
A7: 59 | B7: 22.631 | C7: 0.04419
A8: 60 | B8: 22.044 | C8: 0.04536
A9: 61 | B9: 21.453 | C9: 0.04661
A10: 62 | B10: 20.857 | C10: 0.04795
A11: 63 | B11: 20.258 | C11: 0.04936
A12: 64 | B12: 19.656 | C12: 0.05088
A13: 65 | B13: 19.049 | C13: 0.0525
A14: 66 | B14: 18.441 | C14: 0.05423
A15: 67 | B15: 17.831 | C15: 0.05608
A16: 68 | B16: 17.218 | C16: 0.05808
... A19: 71 | B19: 15.36 | C19: 0.0651
A22: NOTE OPERATIVE:
A23: 1. Tasso di sconto del decreto: 1,5%. Questi valori valgono per pensioni con decorrenza 2025-2026.
A24: 2. Età non intere: coefficiente(y, m) = coef(y) + (m/12) × (coef(y+1) - coef(y))
A25: 3. I coefficienti CALANO ~1,5-2,2% per biennio (speranza di vita). Per pensioni future, il foglio
A26: Input proietta il coefficiente in avanti tramite il 'Decadimento coefficiente / biennio'.
A27: 4. Chi va in pensione tra molti anni avrà un coefficiente più basso di quelli in tabella: la
A28: tabella è la base 2025-2026, la proiezione la riduce per i bienni mancanti.
A29: 5. Per pensionati prossimi: verificare il coefficiente esatto sul sito INPS.

Sheet Pubblica
A1: Proiezione previdenza obbligatoria INPS
A2: Proiezione anno per anno del montante contributivo INPS, in euro di oggi (RAL reale, PIL reale). Il contributo dell'anno si rivaluta dall'anno successivo (L. 335/1995) e la retribuzione oltre il massimale non versa contributi. La pensione usa il coefficiente PROIETTATO all'anno di pensionamento (vedi foglio Input), non quello attuale.
A4: Anno offset | B4: Età | C4: RAL lorda | D4: Contributo (33%, fino al massimale) | E4: Montante inizio | F4: Rivalutazione | G4: Montante fine
A5: 0 | B5: =Input!$B$5+A5 -> 45 | C5: =IF(B5<Input!$B$6, Input!$B$10*(1+Input!$B$12)^A5, 0) -> 45000 | D5: =MIN(C5,Input!$B$43)*Input!$B$13 -> 14850 | E5: =IF(Input!$B$14>0,Input!$B$14,Input!$B$13*SUMPRODUCT((Pubblica!$A$5:$A$54+1<=Input!$B$11)*((Input!$B$10*(1+Input!$B$12)^-(Pubblica!$A$5:$A$54+1)+Input!$B$43-ABS(Input!$B$10*(1+Input!$B$12)^-(Pubblica!$A$5:$A$54+1)-Input!$B$43))/2)*(1+Input!$B$16)^Pubblica!$A$5:$A$54)) -> 242413 | F5: =E5*Input!$B$16 -> 1212.065 | G5: =IF(B5<Input!$B$6, E5+D5+F5, E5) -> 258475.07
A6: 1 | B6: =Input!$B$5+A6 -> 46 | C6: =IF(B6<Input!$B$6, Input!$B$10*(1+Input!$B$12)^A6, 0) -> 45675 | D6: =MIN(C6,Input!$B$43)*Input!$B$13 -> 15072.75 | E6: =G5 -> 258475.07 | F6: =E6*Input!$B$16 -> 1292.3753 | G6: =IF(B6<Input!$B$6, E6+D6+F6, E6) -> 274840.19
A7: 2 | B7: =Input!$B$5+A7 -> 47 | C7: =IF(B7<Input!$B$6, Input!$B$10*(1+Input!$B$12)^A7, 0) -> 46360.125 | D7: =MIN(C7,Input!$B$43)*Input!$B$13 -> 15298.841 | E7: =G6 -> 274840.19 | F7: =E7*Input!$B$16 -> 1374.201 | G7: =IF(B7<Input!$B$6, E7+D7+F7, E7) -> 291513.24
A8: 3 | B8: =Input!$B$5+A8 -> 48 | C8: =IF(B8<Input!$B$6, Input!$B$10*(1+Input!$B$12)^A8, 0) -> 47055.527 | D8: =MIN(C8,Input!$B$43)*Input!$B$13 -> 15528.324 | E8: =G7 -> 291513.24 | F8: =E8*Input!$B$16 -> 1457.5662 | G8: =IF(B8<Input!$B$6, E8+D8+F8, E8) -> 308499.13
A9: 4 | B9: =Input!$B$5+A9 -> 49 | C9: =IF(B9<Input!$B$6, Input!$B$10*(1+Input!$B$12)^A9, 0) -> 47761.36 | D9: =MIN(C9,Input!$B$43)*Input!$B$13 -> 15761.249 | E9: =G8 -> 308499.13 | F9: =E9*Input!$B$16 -> 1542.4956 | G9: =IF(B9<Input!$B$6, E9+D9+F9, E9) -> 325802.87
A10: 5 | B10: =Input!$B$5+A10 -> 50 | C10: =IF(B10<Input!$B$6, Input!$B$10*(1+Input!$B$12)^A10, 0) -> 48477.78 | D10: =MIN(C10,Input!$B$43)*Input!$B$13 -> 15997.667 | E10: =G9 -> 325802.87 | F10: =E10*Input!$B$16 -> 1629.0143 | G10: =IF(B10<Input!$B$6, E10+D10+F10, E10) -> 343429.55
A11: 6 | B11: =Input!$B$5+A11 -> 51 | C11: =IF(B11<Input!$B$6, Input!$B$10*(1+Input!$B$12)^A11, 0) -> 49204.947 | D11: =MIN(C11,Input!$B$43)*Input!$B$13 -> 16237.632 | E11: =G10 -> 343429.55 | F11: =E11*Input!$B$16 -> 1717.1478 | G11: =IF(B11<Input!$B$6, E11+D11+F11, E11) -> 361384.33
A12: 7 | B12: =Input!$B$5+A12 -> 52 | C12: =IF(B12<Input!$B$6, Input!$B$10*(1+Input!$B$12)^A12, 0) -> 49943.021 | D12: =MIN(C12,Input!$B$43)*Input!$B$13 -> 16481.197 | E12: =G11 -> 361384.33 | F12: =E12*Input!$B$16 -> 1806.9217 | G12: =IF(B12<Input!$B$6, E12+D12+F12, E12) -> 379672.45
A13: 8 | B13: =Input!$B$5+A13 -> 53 | C13: =IF(B13<Input!$B$6, Input!$B$10*(1+Input!$B$12)^A13, 0) -> 50692.166 | D13: =MIN(C13,Input!$B$43)*Input!$B$13 -> 16728.415 | E13: =G12 -> 379672.45 | F13: =E13*Input!$B$16 -> 1898.3623 | G13: =IF(B13<Input!$B$6, E13+D13+F13, E13) -> 398299.23
A14: 9 | B14: =Input!$B$5+A14 -> 54 | C14: =IF(B14<Input!$B$6, Input!$B$10*(1+Input!$B$12)^A14, 0) -> 51452.549 | D14: =MIN(C14,Input!$B$43)*Input!$B$13 -> 16979.341 | E14: =G13 -> 398299.23 | F14: =E14*Input!$B$16 -> 1991.4961 | G14: =IF(B14<Input!$B$6, E14+D14+F14, E14) -> 417270.06
A15: 10 | B15: =Input!$B$5+A15 -> 55 | C15: =IF(B15<Input!$B$6, Input!$B$10*(1+Input!$B$12)^A15, 0) -> 52224.337 | D15: =MIN(C15,Input!$B$43)*Input!$B$13 -> 17234.031 | E15: =G14 -> 417270.06 | F15: =E15*Input!$B$16 -> 2086.3503 | G15: =IF(B15<Input!$B$6, E15+D15+F15, E15) -> 436590.45
A16: 11 | B16: =Input!$B$5+A16 -> 56 | C16: =IF(B16<Input!$B$6, Input!$B$10*(1+Input!$B$12)^A16, 0) -> 53007.702 | D16: =MIN(C16,Input!$B$43)*Input!$B$13 -> 17492.542 | E16: =G15 -> 436590.45 | F16: =E16*Input!$B$16 -> 2182.9522 | G16: =IF(B16<Input!$B$6, E16+D16+F16, E16) -> 456265.94
A17: 12 | B17: =Input!$B$5+A17 -> 57 | C17: =IF(B17<Input!$B$6, Input!$B$10*(1+Input!$B$12)^A17, 0) -> 53802.818 | D17: =MIN(C17,Input!$B$43)*Input!$B$13 -> 17754.93 | E17: =G16 -> 456265.94 | F17: =E17*Input!$B$16 -> 2281.3297 | G17: =IF(B17<Input!$B$6, E17+D17+F17, E17) -> 476302.2
... A54: 49 | B54: =Input!$B$5+A54 -> 94 | C54: =IF(B54<Input!$B$6, Input!$B$10*(1+Input!$B$12)^A54, 0) -> 0 | D54: =MIN(C54,Input!$B$43)*Input!$B$13 -> 0 | E54: =G53 -> 673839.6 | F54: =E54*Input!$B$16 -> 3369.198 | G54: =IF(B54<Input!$B$6, E54+D54+F54, E54) -> 673839.6
A57: RISULTATI FINALI A PENSIONAMENTO
A58: Montante INPS finale al pensionamento | B58: =INDEX(G5:G54, MATCH(Input!$B$6-1, B5:B54, 0)) -> 673839.6
A59: Coefficiente ATTUALE 2025-2026 (riferimento) | B59: =VLOOKUP(Input!$B$6, Coefficienti!A5:C19, 3, FALSE()) -> 0.05608
A60: Coefficiente PROIETTATO al pensionamento (usato) | B60: =Input!$B$40 -> 0.045923436
A61: Pensione lorda annua | B61: =B58*B60 -> 30945.03
A62: Pensione lorda mensile (13 mensilità) | B62: =B61/13 -> 2380.3869
A63: IRPEF lorda su pensione (scaglioni 2026) | B63: =IF(B61<=28000, B61*0.23, IF(B61<=50000, 28000*0.23 + (B61-28000)*0.33, 28000*0.23 + 22000*0.33 + (B61-50000)*0.43)) -> 7411.8598
A64: Detrazione pensionati (art. 13 c. 3 TUIR, dal 2027 art. 13 c. 3 D.Lgs. 117/2026) | B64: =IF(B61<=8500, 1955, IF(B61<=28000, 700 + 1255*(28000-B61)/19500, IF(B61<=50000, 700*(50000-B61)/22000, 0))) -> 606.29451
A65: Addizionali regionali + comunali (~2%, se c'è IRPEF) | B65: =IF(B63-B64>0,B61*0.02,0) -> 618.90059
A66: Pensione NETTA annua | B66: =B61-MAX(0,B63-B64)-B65 -> 23520.564
A67: Pensione NETTA mensile | B67: =B66/13 -> 1809.2741
A68: Tasso di sostituzione lordo (pens / RAL finale) | B68: =IFERROR(B61/INDEX(C5:C54, MATCH(Input!$B$6-1, B5:B54, 0)), 0) -> 0.50302724
A70: Nota: il coefficiente proiettato è inferiore a quello attuale perché i coefficienti calano nel tempo (speranza di vita). Usare quello attuale per una pensione lontana SOVRASTIMA l'assegno.

Sheet Complementare
A1: Proiezione previdenza complementare
A2: Proiezione anno per anno del fondo pensione in euro di oggi (TFR se conferito + contributi del lavoratore e del datore + rendimenti), con la quota deducibile e il confronto del TFR in azienda.
A4: Anno offset | B4: Età | C4: RAL lorda | D4: TFR (6,91%) | E4: Contrib. lavoratore | F4: Contrib. datore | G4: Rendimento | H4: Montante fine | I4: Quota deducibile volontario | J4: Non dedotto (da comunicare) | K4: Base tassabile in uscita (€ oggi) | L4: TFR in azienda: quota | M4: TFR in azienda: saldo | N4: TFR nel fondo: montante | O4: TFR: base tassabile (€ oggi)
A5: 0 | B5: =Input!$B$5+A5 -> 45 | C5: =IF(B5<Input!$B$6, Input!$B$10*(1+Input!$B$12)^A5, 0) -> 45000 | D5: =C5*0.0691*Input!$B$21 -> 3109.5 | E5: =IF(B5<Input!$B$6,Input!$B$26+C5*Input!$B$47,0) -> 2000 | F5: =C5*Input!$B$27 -> 675 | G5: =(Input!$B$22*Input!$B$21+Input!$B$25)*Input!$B$28 -> 325 | H5: =Input!$B$22*Input!$B$21+Input!$B$25+D5+E5+F5+G5 -> 19109.5 | I5: =MIN(Input!$B$44,E5+F5)-MIN(Input!$B$44,F5+C5*Input!$B$47) -> 2000 | J5: =E5+F5-MIN(Input!$B$44,E5+F5) -> 0 | K5: =(D5+MIN(Input!$B$44,E5+F5))*(1+Input!$B$17)^(A5-Input!$B$36) -> 3741.6404 | L5: =C5*0.0691 -> 3109.5 | M5: =IF(B5<Input!$B$6,Input!$B$22*Input!$B$21*(1+Input!$B$49)+L5,Input!$B$22*Input!$B$21) -> 11147.931 | N5: =IF(B5<Input!$B$6,Input!$B$22*Input!$B$21*(1+Input!$B$28)+L5,Input!$B$22*Input!$B$21) -> 11309.5 | O5: =L5*(1+Input!$B$17)^(A5-Input!$B$36) -> 2011.346
A6: 1 | B6: =Input!$B$5+A6 -> 46 | C6: =IF(B6<Input!$B$6, Input!$B$10*(1+Input!$B$12)^A6, 0) -> 45675 | D6: =C6*0.0691*Input!$B$21 -> 3156.1425 | E6: =IF(B6<Input!$B$6,Input!$B$26+C6*Input!$B$47,0) -> 2000 | F6: =C6*Input!$B$27 -> 685.125 | G6: =H5*Input!$B$28 -> 477.7375 | H6: =H5+D6+E6+F6+G6 -> 25428.505 | I6: =MIN(Input!$B$44,E6+F6)-MIN(Input!$B$44,F6+C6*Input!$B$47) -> 2000 | J6: =E6+F6-MIN(Input!$B$44,E6+F6) -> 0 | K6: =(D6+MIN(Input!$B$44,E6+F6))*(1+Input!$B$17)^(A6-Input!$B$36) -> 3853.927 | L6: =C6*0.0691 -> 3156.1425 | M6: =IF(B6<Input!$B$6,M5*(1+Input!$B$49)+L6,M5) -> 14357.628 | N6: =IF(B6<Input!$B$6,N5*(1+Input!$B$28)+L6,N5) -> 14748.38 | O6: =L6*(1+Input!$B$17)^(A6-Input!$B$36) -> 2082.3465
A7: 2 | B7: =Input!$B$5+A7 -> 47 | C7: =IF(B7<Input!$B$6, Input!$B$10*(1+Input!$B$12)^A7, 0) -> 46360.125 | D7: =C7*0.0691*Input!$B$21 -> 3203.4846 | E7: =IF(B7<Input!$B$6,Input!$B$26+C7*Input!$B$47,0) -> 2000 | F7: =C7*Input!$B$27 -> 695.40188 | G7: =H6*Input!$B$28 -> 635.71263 | H7: =H6+D7+E7+F7+G7 -> 31963.104 | I7: =MIN(Input!$B$44,E7+F7)-MIN(Input!$B$44,F7+C7*Input!$B$47) -> 2000 | J7: =E7+F7-MIN(Input!$B$44,E7+F7) -> 0 | K7: =(D7+MIN(Input!$B$44,E7+F7))*(1+Input!$B$17)^(A7-Input!$B$36) -> 3969.7815 | L7: =C7*0.0691 -> 3203.4846 | M7: =IF(B7<Input!$B$6,M6*(1+Input!$B$49)+L7,M6) -> 17630.085 | N7: =IF(B7<Input!$B$6,N6*(1+Input!$B$28)+L7,N6) -> 18320.574 | O7: =L7*(1+Input!$B$17)^(A7-Input!$B$36) -> 2155.8533
A8: 3 | B8: =Input!$B$5+A8 -> 48 | C8: =IF(B8<Input!$B$6, Input!$B$10*(1+Input!$B$12)^A8, 0) -> 47055.527 | D8: =C8*0.0691*Input!$B$21 -> 3251.5369 | E8: =IF(B8<Input!$B$6,Input!$B$26+C8*Input!$B$47,0) -> 2000 | F8: =C8*Input!$B$27 -> 705.8329 | G8: =H7*Input!$B$28 -> 799.0776 | H8: =H7+D8+E8+F8+G8 -> 38719.552 | I8: =MIN(Input!$B$44,E8+F8)-MIN(Input!$B$44,F8+C8*Input!$B$47) -> 2000 | J8: =E8+F8-MIN(Input!$B$44,E8+F8) -> 0 | K8: =(D8+MIN(Input!$B$44,E8+F8))*(1+Input!$B$17)^(A8-Input!$B$36) -> 4089.3219 | L8: =C8*0.0691 -> 3251.5369 | M8: =IF(B8<Input!$B$6,M7*(1+Input!$B$49)+L8,M7) -> 20966.316 | N8: =IF(B8<Input!$B$6,N7*(1+Input!$B$28)+L8,N7) -> 22030.125 | O8: =L8*(1+Input!$B$17)^(A8-Input!$B$36) -> 2231.9549
A9: 4 | B9: =Input!$B$5+A9 -> 49 | C9: =IF(B9<Input!$B$6, Input!$B$10*(1+Input!$B$12)^A9, 0) -> 47761.36 | D9: =C9*0.0691*Input!$B$21 -> 3300.31 | E9: =IF(B9<Input!$B$6,Input!$B$26+C9*Input!$B$47,0) -> 2000 | F9: =C9*Input!$B$27 -> 716.4204 | G9: =H8*Input!$B$28 -> 967.98879 | H9: =H8+D9+E9+F9+G9 -> 45704.271 | I9: =MIN(Input!$B$44,E9+F9)-MIN(Input!$B$44,F9+C9*Input!$B$47) -> 2000 | J9: =E9+F9-MIN(Input!$B$44,E9+F9) -> 0 | K9: =(D9+MIN(Input!$B$44,E9+F9))*(1+Input!$B$17)^(A9-Input!$B$36) -> 4212.6702 | L9: =C9*0.0691 -> 3300.31 | M9: =IF(B9<Input!$B$6,M8*(1+Input!$B$49)+L9,M8) -> 24367.346 | N9: =IF(B9<Input!$B$6,N8*(1+Input!$B$28)+L9,N8) -> 25881.188 | O9: =L9*(1+Input!$B$17)^(A9-Input!$B$36) -> 2310.743
A10: 5 | B10: =Input!$B$5+A10 -> 50 | C10: =IF(B10<Input!$B$6, Input!$B$10*(1+Input!$B$12)^A10, 0) -> 48477.78 | D10: =C10*0.0691*Input!$B$21 -> 3349.8146 | E10: =IF(B10<Input!$B$6,Input!$B$26+C10*Input!$B$47,0) -> 2000 | F10: =C10*Input!$B$27 -> 727.1667 | G10: =H9*Input!$B$28 -> 1142.6068 | H10: =H9+D10+E10+F10+G10 -> 52923.859 | I10: =MIN(Input!$B$44,E10+F10)-MIN(Input!$B$44,F10+C10*Input!$B$47) -> 2000 | J10: =E10+F10-MIN(Input!$B$44,E10+F10) -> 0 | K10: =(D10+MIN(Input!$B$44,E10+F10))*(1+Input!$B$17)^(A10-Input!$B$36) -> 4339.9525 | L10: =C10*0.0691 -> 3349.8146 | M10: =IF(B10<Input!$B$6,M9*(1+Input!$B$49)+L10,M9) -> 27834.22 | N10: =IF(B10<Input!$B$6,N9*(1+Input!$B$28)+L10,N9) -> 29878.033 | O10: =L10*(1+Input!$B$17)^(A10-Input!$B$36) -> 2392.3122
A11: 6 | B11: =Input!$B$5+A11 -> 51 | C11: =IF(B11<Input!$B$6, Input!$B$10*(1+Input!$B$12)^A11, 0) -> 49204.947 | D11: =C11*0.0691*Input!$B$21 -> 3400.0618 | E11: =IF(B11<Input!$B$6,Input!$B$26+C11*Input!$B$47,0) -> 2000 | F11: =C11*Input!$B$27 -> 738.0742 | G11: =H10*Input!$B$28 -> 1323.0965 | H11: =H10+D11+E11+F11+G11 -> 60385.091 | I11: =MIN(Input!$B$44,E11+F11)-MIN(Input!$B$44,F11+C11*Input!$B$47) -> 2000 | J11: =E11+F11-MIN(Input!$B$44,E11+F11) -> 0 | K11: =(D11+MIN(Input!$B$44,E11+F11))*(1+Input!$B$17)^(A11-Input!$B$36) -> 4471.2995 | L11: =C11*0.0691 -> 3400.0618 | M11: =IF(B11<Input!$B$6,M10*(1+Input!$B$49)+L11,M10) -> 31367.995 | N11: =IF(B11<Input!$B$6,N10*(1+Input!$B$28)+L11,N10) -> 34025.045 | O11: =L11*(1+Input!$B$17)^(A11-Input!$B$36) -> 2476.7608
A12: 7 | B12: =Input!$B$5+A12 -> 52 | C12: =IF(B12<Input!$B$6, Input!$B$10*(1+Input!$B$12)^A12, 0) -> 49943.021 | D12: =C12*0.0691*Input!$B$21 -> 3451.0628 | E12: =IF(B12<Input!$B$6,Input!$B$26+C12*Input!$B$47,0) -> 2000 | F12: =C12*Input!$B$27 -> 749.14532 | G12: =H11*Input!$B$28 -> 1509.6273 | H12: =H11+D12+E12+F12+G12 -> 68094.927 | I12: =MIN(Input!$B$44,E12+F12)-MIN(Input!$B$44,F12+C12*Input!$B$47) -> 2000 | J12: =E12+F12-MIN(Input!$B$44,E12+F12) -> 0 | K12: =(D12+MIN(Input!$B$44,E12+F12))*(1+Input!$B$17)^(A12-Input!$B$36) -> 4606.8459 | L12: =C12*0.0691 -> 3451.0628 | M12: =IF(B12<Input!$B$6,M11*(1+Input!$B$49)+L12,M11) -> 34969.747 | N12: =IF(B12<Input!$B$6,N11*(1+Input!$B$28)+L12,N11) -> 38326.734 | O12: =L12*(1+Input!$B$17)^(A12-Input!$B$36) -> 2564.1905
A13: 8 | B13: =Input!$B$5+A13 -> 53 | C13: =IF(B13<Input!$B$6, Input!$B$10*(1+Input!$B$12)^A13, 0) -> 50692.166 | D13: =C13*0.0691*Input!$B$21 -> 3502.8287 | E13: =IF(B13<Input!$B$6,Input!$B$26+C13*Input!$B$47,0) -> 2000 | F13: =C13*Input!$B$27 -> 760.3825 | G13: =H12*Input!$B$28 -> 1702.3732 | H13: =H12+D13+E13+F13+G13 -> 76060.511 | I13: =MIN(Input!$B$44,E13+F13)-MIN(Input!$B$44,F13+C13*Input!$B$47) -> 2000 | J13: =E13+F13-MIN(Input!$B$44,E13+F13) -> 0 | K13: =(D13+MIN(Input!$B$44,E13+F13))*(1+Input!$B$17)^(A13-Input!$B$36) -> 4746.7313 | L13: =C13*0.0691 -> 3502.8287 | M13: =IF(B13<Input!$B$6,M12*(1+Input!$B$49)+L13,M12) -> 38640.568 | N13: =IF(B13<Input!$B$6,N12*(1+Input!$B$28)+L13,N12) -> 42787.731 | O13: =L13*(1+Input!$B$17)^(A13-Input!$B$36) -> 2654.7064
A14: 9 | B14: =Input!$B$5+A14 -> 54 | C14: =IF(B14<Input!$B$6, Input!$B$10*(1+Input!$B$12)^A14, 0) -> 51452.549 | D14: =C14*0.0691*Input!$B$21 -> 3555.3711 | E14: =IF(B14<Input!$B$6,Input!$B$26+C14*Input!$B$47,0) -> 2000 | F14: =C14*Input!$B$27 -> 771.78823 | G14: =H13*Input!$B$28 -> 1901.5128 | H14: =H13+D14+E14+F14+G14 -> 84289.183 | I14: =MIN(Input!$B$44,E14+F14)-MIN(Input!$B$44,F14+C14*Input!$B$47) -> 2000 | J14: =E14+F14-MIN(Input!$B$44,E14+F14) -> 0 | K14: =(D14+MIN(Input!$B$44,E14+F14))*(1+Input!$B$17)^(A14-Input!$B$36) -> 4891.1 | L14: =C14*0.0691 -> 3555.3711 | M14: =IF(B14<Input!$B$6,M13*(1+Input!$B$49)+L14,M13) -> 42381.565 | N14: =IF(B14<Input!$B$6,N13*(1+Input!$B$28)+L14,N13) -> 47412.796 | O14: =L14*(1+Input!$B$17)^(A14-Input!$B$36) -> 2748.4175
A15: 10 | B15: =Input!$B$5+A15 -> 55 | C15: =IF(B15<Input!$B$6, Input!$B$10*(1+Input!$B$12)^A15, 0) -> 52224.337 | D15: =C15*0.0691*Input!$B$21 -> 3608.7017 | E15: =IF(B15<Input!$B$6,Input!$B$26+C15*Input!$B$47,0) -> 2000 | F15: =C15*Input!$B$27 -> 783.36506 | G15: =H14*Input!$B$28 -> 2107.2296 | H15: =H14+D15+E15+F15+G15 -> 92788.479 | I15: =MIN(Input!$B$44,E15+F15)-MIN(Input!$B$44,F15+C15*Input!$B$47) -> 2000 | J15: =E15+F15-MIN(Input!$B$44,E15+F15) -> 0 | K15: =(D15+MIN(Input!$B$44,E15+F15))*(1+Input!$B$17)^(A15-Input!$B$36) -> 5040.101 | L15: =C15*0.0691 -> 3608.7017 | M15: =IF(B15<Input!$B$6,M14*(1+Input!$B$49)+L15,M14) -> 46193.864 | N15: =IF(B15<Input!$B$6,N14*(1+Input!$B$28)+L15,N14) -> 52206.817 | O15: =L15*(1+Input!$B$17)^(A15-Input!$B$36) -> 2845.4367
A16: 11 | B16: =Input!$B$5+A16 -> 56 | C16: =IF(B16<Input!$B$6, Input!$B$10*(1+Input!$B$12)^A16, 0) -> 53007.702 | D16: =C16*0.0691*Input!$B$21 -> 3662.8322 | E16: =IF(B16<Input!$B$6,Input!$B$26+C16*Input!$B$47,0) -> 2000 | F16: =C16*Input!$B$27 -> 795.11553 | G16: =H15*Input!$B$28 -> 2319.712 | H16: =H15+D16+E16+F16+G16 -> 101566.14 | I16: =MIN(Input!$B$44,E16+F16)-MIN(Input!$B$44,F16+C16*Input!$B$47) -> 2000 | J16: =E16+F16-MIN(Input!$B$44,E16+F16) -> 0 | K16: =(D16+MIN(Input!$B$44,E16+F16))*(1+Input!$B$17)^(A16-Input!$B$36) -> 5193.8887 | L16: =C16*0.0691 -> 3662.8322 | M16: =IF(B16<Input!$B$6,M15*(1+Input!$B$49)+L16,M15) -> 50078.608 | N16: =IF(B16<Input!$B$6,N15*(1+Input!$B$28)+L16,N15) -> 57174.82 | O16: =L16*(1+Input!$B$17)^(A16-Input!$B$36) -> 2945.8806
A17: 12 | B17: =Input!$B$5+A17 -> 57 | C17: =IF(B17<Input!$B$6, Input!$B$10*(1+Input!$B$12)^A17, 0) -> 53802.818 | D17: =C17*0.0691*Input!$B$21 -> 3717.7747 | E17: =IF(B17<Input!$B$6,Input!$B$26+C17*Input!$B$47,0) -> 2000 | F17: =C17*Input!$B$27 -> 807.04227 | G17: =H16*Input!$B$28 -> 2539.1535 | H17: =H16+D17+E17+F17+G17 -> 110630.11 | I17: =MIN(Input!$B$44,E17+F17)-MIN(Input!$B$44,F17+C17*Input!$B$47) -> 2000 | J17: =E17+F17-MIN(Input!$B$44,E17+F17) -> 0 | K17: =(D17+MIN(Input!$B$44,E17+F17))*(1+Input!$B$17)^(A17-Input!$B$36) -> 5352.6225 | L17: =C17*0.0691 -> 3717.7747 | M17: =IF(B17<Input!$B$6,M16*(1+Input!$B$49)+L17,M16) -> 54036.957 | N17: =IF(B17<Input!$B$6,N16*(1+Input!$B$28)+L17,N16) -> 62321.965 | O17: =L17*(1+Input!$B$17)^(A17-Input!$B$36) -> 3049.8702
... A54: 49 | B54: =Input!$B$5+A54 -> 94 | C54: =IF(B54<Input!$B$6, Input!$B$10*(1+Input!$B$12)^A54, 0) -> 0 | D54: =C54*0.0691*Input!$B$21 -> 0 | E54: =IF(B54<Input!$B$6,Input!$B$26+C54*Input!$B$47,0) -> 0 | F54: =C54*Input!$B$27 -> 0 | G54: =H53*Input!$B$28 -> 10056.07 | H54: =H53+D54+E54+F54+G54 -> 412298.89 | I54: =MIN(Input!$B$44,E54+F54)-MIN(Input!$B$44,F54+C54*Input!$B$47) -> 0 | J54: =E54+F54-MIN(Input!$B$44,E54+F54) -> 0 | K54: =(D54+MIN(Input!$B$44,E54+F54))*(1+Input!$B$17)^(A54-Input!$B$36) -> 0 | L54: =C54*0.0691 -> 0 | M54: =IF(B54<Input!$B$6,M53*(1+Input!$B$49)+L54,M53) -> 93174.694 | N54: =IF(B54<Input!$B$6,N53*(1+Input!$B$28)+L54,N53) -> 117632.27 | O54: =L54*(1+Input!$B$17)^(A54-Input!$B$36) -> 0
A57: RISULTATI FINALI A PENSIONAMENTO
A58: Montante fondo finale (lordo) | B58: =INDEX(H5:H54, MATCH(Input!$B$6-1, B5:B54, 0)) -> 206511.35
A59: Aliquota fondo finale (da Input) | B59: =Input!$B$38 -> 0.114
A60: Tassazione finale (TFR e contributi dedotti × aliquota) | B60: =((Input!$B$22*Input!$B$21+Input!$B$25)*(1+Input!$B$17)^(-Input!$B$36)+SUM(K5:K54))*Input!$B$38 -> 14037.712
A61: Prestazione fondo NETTA | B61: =B58-B60 -> 192473.64
A62: Rendita annua stimata (~5,5% del netto) | B62: =B61*0.055 -> 10586.05
A63: Rendita lorda mensile (13 mensilità) | B63: =B62/13 -> 814.31156
A64: Risparmio IRPEF cumulato sui volontari (quota deducibile) | B64: =SUM(I5:I54)*Input!$B$37 -> 14520
A66: NOTE:
A67: 1. Contributo volontario costante in termini reali: tutto il foglio è in euro di oggi.
A68: 2. Rendimento netto REALE del comparto: al netto dei costi, della tassa annua del 20% (12,5% titoli di Stato) e dell'inflazione.
A69: 3. Aliquota finale 15% → 9% sui soli TFR e contributi dedotti: rendimenti già tassati e non dedotti comunicati sono esclusi (art. 11 c. 6 D.Lgs. 252/2005; dal 2027 art. 258 c. 4 D.Lgs. 117/2026). Il montante già accumulato è trattato come dedotto.
A70: 4. Tasso conversione rendita 5,5%: vitalizia a 67 anni senza reversibilità.
A71: 5. Risparmio IRPEF nominale non scontato, solo sulla quota deducibile dei volontari (colonna I).
A73: PLAFOND DI DEDUCIBILITÀ (art. 8 c. 4 D.Lgs. 252/2005)
A74: Spazio deducibile residuo per i volontari (primo anno) | B74: =MAX(0,Input!$B$44-F5-C5*Input!$B$47) -> 4625
A75: Non dedotto da comunicare al fondo (somma degli anni) | B75: =SUM(J5:J54) -> 0
A76: Lo spazio residuo è un tetto fiscale, non un importo consigliato: dipende da liquidità e alternative. Non è consulenza.
A77: Ciò che supera il plafond va comunicato al fondo entro il 31/12 dell'anno dopo: senza comunicazione in uscita è tassato di nuovo (9-15% del non dedotto, 23% con anticipazioni non sanitarie o riscatti per altre cause).
A79: CONFRONTO TFR: IN AZIENDA O NEL FONDO (€ di oggi; TFR futuro, più il saldo solo se è già nel fondo: il maturato in azienda ci resta)
A80: TFR in azienda al pensionamento (lordo) | B80: =INDEX(M5:M54,MATCH(Input!$B$6-1,B5:B54,0)) -> 93174.694
A81: Base della tassazione (quote, senza rivalutazioni) | B81: =Input!$B$22*Input!$B$21*(1+Input!$B$17)^(-Input!$B$36)+SUM(O5:O54) -> 70423.532
A82: Reddito di riferimento (base × 12 / anni di servizio) | B82: =B81*12/(Input!$B$48*Input!$B$21+Input!$B$36) -> 33803.295
...

Sheet Scenari
A1: Confronto scenari: conservativo / base / ottimistico
A2: Tutto in euro di oggi. Base coincide con i fogli Pubblica e Complementare; Conservativo e Ottimistico ricalcolano pensione INPS e fondo con i parametri della propria colonna.
A4: Voce | B4: Conservativo | C4: Base | D4: Ottimistico
A5: Crescita RAL annua reale | B5: =Input!$B$12-0.01 -> 0.005 | C5: =Input!$B$12 -> 0.015 | D5: =Input!$B$12+0.01 -> 0.025
A6: Rivalutazione PIL reale annua | B6: =MAX(0,Input!$B$16-0.005) -> 0 | C6: =Input!$B$16 -> 0.005 | D6: =Input!$B$16+0.005 -> 0.01
A7: Inflazione attesa (solo vista nominale, riga 21) | B7: =Input!$B$17+0.005 -> 0.025 | C7: =Input!$B$17 -> 0.02 | D7: =MAX(0,Input!$B$17-0.005) -> 0.015
A8: Decadimento coefficiente / biennio | B8: =Input!$B$18+0.004 -> 0.022 | C8: =Input!$B$18 -> 0.018 | D8: =MAX(0,Input!$B$18-0.003) -> 0.015
A9: Rendimento netto reale comparto | B9: =Input!$B$28-0.01 -> 0.015 | C9: =Input!$B$28 -> 0.025 | D9: =Input!$B$28+0.01 -> 0.035
A11: Pensione INPS lorda annua | B11: =(Pubblica!$E$5*(1+B6)^Input!$B$36+SUMPRODUCT((Pubblica!$A$5:$A$54<Input!$B$36)*((Input!$B$10*(1+B5)^Pubblica!$A$5:$A$54+Input!$B$43-ABS(Input!$B$10*(1+B5)^Pubblica!$A$5:$A$54-Input!$B$43))/2)*Input!$B$13*(1+B6)^(Input!$B$36-1-Pubblica!$A$5:$A$54)))*VLOOKUP(Input!$B$6,Coefficienti!$A$5:$C$19,3,FALSE())*(1-B8)^(Input!$B$36/2) -> 25766.934 | C11: =(Pubblica!$E$5*(1+C6)^Input!$B$36+SUMPRODUCT((Pubblica!$A$5:$A$54<Input!$B$36)*((Input!$B$10*(1+C5)^Pubblica!$A$5:$A$54+Input!$B$43-ABS(Input!$B$10*(1+C5)^Pubblica!$A$5:$A$54-Input!$B$43))/2)*Input!$B$13*(1+C6)^(Input!$B$36-1-Pubblica!$A$5:$A$54)))*VLOOKUP(Input!$B$6,Coefficienti!$A$5:$C$19,3,FALSE())*(1-C8)^(Input!$B$36/2) -> 30945.03 | D11: =(Pubblica!$E$5*(1+D6)^Input!$B$36+SUMPRODUCT((Pubblica!$A$5:$A$54<Input!$B$36)*((Input!$B$10*(1+D5)^Pubblica!$A$5:$A$54+Input!$B$43-ABS(Input!$B$10*(1+D5)^Pubblica!$A$5:$A$54-Input!$B$43))/2)*Input!$B$13*(1+D6)^(Input!$B$36-1-Pubblica!$A$5:$A$54)))*VLOOKUP(Input!$B$6,Coefficienti!$A$5:$C$19,3,FALSE())*(1-D8)^(Input!$B$36/2) -> 36749.19
A12: Pensione INPS netta annua (IRPEF del foglio Pubblica) | B12: =B11-MAX(0,IF(B11<=28000,B11*0.23,IF(B11<=50000,6440+(B11-28000)*0.33,13700+(B11-50000)*0.43))-IF(B11<=8500,1955,IF(B11<=28000,700+1255*(28000-B11)/19500,IF(B11<=50000,700*(50000-B11)/22000,0))))-IF(IF(B11<=28000,B11*0.23,IF(B11<=50000,6440+(B11-28000)*0.33,13700+(B11-50000)*0.43))-IF(B11<=8500,1955,IF(B11<=28000,700+1255*(28000-B11)/19500,IF(B11<=50000,700*(50000-B11)/22000,0)))>0,B11*0.02,0) -> 20168.918 | C12: =C11-MAX(0,IF(C11<=28000,C11*0.23,IF(C11<=50000,6440+(C11-28000)*0.33,13700+(C11-50000)*0.43))-IF(C11<=8500,1955,IF(C11<=28000,700+1255*(28000-C11)/19500,IF(C11<=50000,700*(50000-C11)/22000,0))))-IF(IF(C11<=28000,C11*0.23,IF(C11<=50000,6440+(C11-28000)*0.33,13700+(C11-50000)*0.43))-IF(C11<=8500,1955,IF(C11<=28000,700+1255*(28000-C11)/19500,IF(C11<=50000,700*(50000-C11)/22000,0)))>0,C11*0.02,0) -> 23520.564 | D12: =D11-MAX(0,IF(D11<=28000,D11*0.23,IF(D11<=50000,6440+(D11-28000)*0.33,13700+(D11-50000)*0.43))-IF(D11<=8500,1955,IF(D11<=28000,700+1255*(28000-D11)/19500,IF(D11<=50000,700*(50000-D11)/22000,0))))-IF(IF(D11<=28000,D11*0.23,IF(D11<=50000,6440+(D11-28000)*0.33,13700+(D11-50000)*0.43))-IF(D11<=8500,1955,IF(D11<=28000,700+1255*(28000-D11)/19500,IF(D11<=50000,700*(50000-D11)/22000,0)))>0,D11*0.02,0) -> 27108.59
A13: Montante fondo finale | B13: =(Input!$B$22*Input!$B$21+Input!$B$25)*(1+B9)^Input!$B$36+SUMPRODUCT((Complementare!$A$5:$A$54<Input!$B$36)*(Input!$B$10*(1+B5)^Complementare!$A$5:$A$54*(0.0691*Input!$B$21+Input!$B$27+Input!$B$47)+Input!$B$26)*(1+B9)^(Input!$B$36-1-Complementare!$A$5:$A$54)) -> 172497.31 | C13: =(Input!$B$22*Input!$B$21+Input!$B$25)*(1+C9)^Input!$B$36+SUMPRODUCT((Complementare!$A$5:$A$54<Input!$B$36)*(Input!$B$10*(1+C5)^Complementare!$A$5:$A$54*(0.0691*Input!$B$21+Input!$B$27+Input!$B$47)+Input!$B$26)*(1+C9)^(Input!$B$36-1-Complementare!$A$5:$A$54)) -> 206511.35 | D13: =(Input!$B$22*Input!$B$21+Input!$B$25)*(1+D9)^Input!$B$36+SUMPRODUCT((Complementare!$A$5:$A$54<Input!$B$36)*(Input!$B$10*(1+D5)^Complementare!$A$5:$A$54*(0.0691*Input!$B$21+Input!$B$27+Input!$B$47)+Input!$B$26)*(1+D9)^(Input!$B$36-1-Complementare!$A$5:$A$54)) -> 247509.32
A14: Prestazione fondo netta | B14: =B13-((Input!$B$22*Input!$B$21+Input!$B$25)*(1+B7)^(-Input!$B$36)+SUMPRODUCT((Complementare!$A$5:$A$54<Input!$B$36)*(Input!$B$10*(1+B5)^Complementare!$A$5:$A$54*0.0691*Input!$B$21+((Input!$B$44+(Input!$B$26+Input!$B$10*(1+B5)^Complementare!$A$5:$A$54*(Input!$B$47+Input!$B$27))-ABS(Input!$B$44-(Input!$B$26+Input!$B$10*(1+B5)^Complementare!$A$5:$A$54*(Input!$B$47+Input!$B$27))))/2))*(1+B7)^(Complementare!$A$5:$A$54-Input!$B$36)))*Input!$B$38 -> 160150.45 | C14: =C13-((Input!$B$22*Input!$B$21+Input!$B$25)*(1+C7)^(-Input!$B$36)+SUMPRODUCT((Complementare!$A$5:$A$54<Input!$B$36)*(Input!$B$10*(1+C5)^Complementare!$A$5:$A$54*0.0691*Input!$B$21+((Input!$B$44+(Input!$B$26+Input!$B$10*(1+C5)^Complementare!$A$5:$A$54*(Input!$B$47+Input!$B$27))-ABS(Input!$B$44-(Input!$B$26+Input!$B$10*(1+C5)^Complementare!$A$5:$A$54*(Input!$B$47+Input!$B$27))))/2))*(1+C7)^(Complementare!$A$5:$A$54-Input!$B$36)))*Input!$B$38 -> 192473.64 | D14: =D13-((Input!$B$22*Input!$B$21+Input!$B$25)*(1+D7)^(-Input!$B$36)+SUMPRODUCT((Complementare!$A$5:$A$54<Input!$B$36)*(Input!$B$10*(1+D5)^Complementare!$A$5:$A$54*0.0691*Input!$B$21+((Input!$B$44+(Input!$B$26+Input!$B$10*(1+D5)^Complementare!$A$5:$A$54*(Input!$B$47+Input!$B$27))-ABS(Input!$B$44-(Input!$B$26+Input!$B$10*(1+D5)^Complementare!$A$5:$A$54*(Input!$B$47+Input!$B$27))))/2))*(1+D7)^(Complementare!$A$5:$A$54-Input!$B$36)))*Input!$B$38 -> 231500.62
A15: Rendita fondo annua (stima) | B15: =B14*0.055 -> 8808.2747 | C15: =C14*0.055 -> 10586.05 | D15: =D14*0.055 -> 12732.534
A16: TFR in azienda netto (capitale, fuori dalla rendita) | B16: =IF(Input!$B$21=0,B31-B32*B33,0) -> 0 | C16: =IF(Input!$B$21=0,C31-C32*C33,0) -> 0 | D16: =IF(Input!$B$21=0,D31-D32*D33,0) -> 0
A17: Reddito pensione totale netto annuo | B17: =B12+B15 -> 28977.193 | C17: =C12+C15 -> 34106.614 | D17: =D12+D15 -> 39841.124
A18: Spesa target annua (€ di oggi) | B18: =Input!$B$39 -> 23400 | C18: =Input!$B$39 -> 23400 | D18: =Input!$B$39 -> 23400
A19: GAP (spesa target - reddito pensione) | B19: =B18-B17 -> -5577.1929 | C19: =C18-C17 -> -10706.614 | D19: =D18-D17 -> -16441.124
A20: Gap % della spesa target | B20: =IFERROR(B19/B18, 0) -> -0.23834158 | C20: =IFERROR(C19/C18, 0) -> -0.45754761 | D20: =IFERROR(D19/D18, 0) -> -0.70261215
A21: GAP in € del pensionamento (inflazione dello scenario) | B21: =B19*(1+B7)^Input!$B$36 -> -9601.5358 | C21: =C19*(1+C7)^Input!$B$36 -> -16552.208 | D21: =D19*(1+D7)^Input!$B$36 -> -22813.107
A22: INTERPRETAZIONE:
A23: • GAP > 0: la pensione totale netta NON copre la spesa target → servono strategie
A24: • GAP < 0: over-saving → margine per consumi extra o lascito
A25: • Tutto in euro di oggi: RAL e PIL reali, spesa target senza inflazione. Conservativo e ottimistico
A26: ricalcolano INPS e fondo con la propria crescita RAL, PIL reale, decadimento e rendimento.
A27: • Fondo: montante, tassa in uscita (solo TFR e dedotti) e rendita col rendimento della colonna; il TFR in azienda (riga 16) è capitale, fuori dal gap: la riga 34 lo traduce in rendita equivalente per il confronto.
A28: • L'inflazione (riga 7) entra solo sulle basi imponibili nominali (TFR in azienda, base del fondo in uscita) e nella riga 21. Soglie fiscali (scaglioni, plafond €5.300) restano quelle di oggi in euro di oggi, come in netto-pensione.py: se la legge non le aggiorna, l'imposta reale cresce.
A30: CALCOLI DI SUPPORTO — TFR in azienda per scenario
A31: TFR in azienda lordo al pensionamento | B31: =Input!$B$22*(1+((1+(0.015+0.75*B7)*(1-0.17))/(1+B7)-1))^Input!$B$36+SUMPRODUCT((Complementare!$A$5:$A$54<Input!$B$36)*Input!$B$10*(1+B5)^Complementare!$A$5:$A$54*0.0691*(1+((1+(0.015+0.75*B7)*(1-0.17))/(1+B7)-1))^(Input!$B$36-1-Complementare!$A$5:$A$54)) -> 82882.746 | C31: =Input!$B$22*(1+((1+(0.015+0.75*C7)*(1-0.17))/(1+C7)-1))^Input!$B$36+SUMPRODUCT((Complementare!$A$5:$A$54<Input!$B$36)*Input!$B$10*(1+C5)^Complementare!$A$5:$A$54*0.0691*(1+((1+(0.015+0.75*C7)*(1-0.17))/(1+C7)-1))^(Input!$B$36-1-Complementare!$A$5:$A$54)) -> 93174.694 | D31: =Input!$B$22*(1+((1+(0.015+0.75*D7)*(1-0.17))/(1+D7)-1))^Input!$B$36+SUMPRODUCT((Complementare!$A$5:$A$54<Input!$B$36)*Input!$B$10*(1+D5)^Complementare!$A$5:$A$54*0.0691*(1+((1+(0.015+0.75*D7)*(1-0.17))/(1+D7)-1))^(Input!$B$36-1-Complementare!$A$5:$A$54)) -> 104970.31
A32: Base della tassazione separata | B32: =Input!$B$22*(1+B7)^(-Input!$B$36)+SUMPRODUCT((Complementare!$A$5:$A$54<Input!$B$36)*Input!$B$10*(1+B5)^Complementare!$A$5:$A$54*0.0691*(1+B7)^(Complementare!$A$5:$A$54-Input!$B$36)) -> 59880.668 | C32: =Input!$B$22*(1+C7)^(-Input!$B$36)+SUMPRODUCT((Complementare!$A$5:$A$54<Input!$B$36)*Input!$B$10*(1+C5)^Complementare!$A$5:$A$54*0.0691*(1+C7)^(Complementare!$A$5:$A$54-Input!$B$36)) -> 70423.532 | D32: =Input!$B$22*(1+D7)^(-Input!$B$36)+SUMPRODUCT((Complementare!$A$5:$A$54<Input!$B$36)*Input!$B$10*(1+D5)^Complementare!$A$5:$A$54*0.0691*(1+D7)^(Complementare!$A$5:$A$54-Input!$B$36)) -> 82849.044
A33: Aliquota media della tassazione separata | B33: =IF((B32*12/(Input!$B$48+Input!$B$36))<=0,0,IF((B32*12/(Input!$B$48+Input!$B$36))<=28000,(B32*12/(Input!$B$48+Input!$B$36))*0.23,IF((B32*12/(Input!$B$48+Input!$B$36))<=50000,6440+((B32*12/(Input!$B$48+Input!$B$36))-28000)*0.33,13700+((B32*12/(Input!$B$48+Input!$B$36))-50000)*0.43))/(B32*12/(Input!$B$48+Input!$B$36))) -> 0.23258403 | C33: =IF((C32*12/(Input!$B$48+Input!$B$36))<=0,0,IF((C32*12/(Input!$B$48+Input!$B$36))<=28000,(C32*12/(Input!$B$48+Input!$B$36))*0.23,IF((C32*12/(Input!$B$48+Input!$B$36))<=50000,6440+((C32*12/(Input!$B$48+Input!$B$36))-28000)*0.33,13700+((C32*12/(Input!$B$48+Input!$B$36))-50000)*0.43))/(C32*12/(Input!$B$48+Input!$B$36))) -> 0.24716784 | D33: =IF((D32*12/(Input!$B$48+Input!$B$36))<=0,0,IF((D32*12/(Input!$B$48+Input!$B$36))<=28000,(D32*12/(Input!$B$48+Input!$B$36))*0.23,IF((D32*12/(Input!$B$48+Input!$B$36))<=50000,6440+((D32*12/(Input!$B$48+Input!$B$36))-28000)*0.33,13700+((D32*12/(Input!$B$48+Input!$B$36))-50000)*0.43))/(D32*12/(Input!$B$48+Input!$B$36))) -> 0.25959082
A34: TFR in azienda come rendita equivalente (5,5%, solo confronto, fuori dal gap) | B34: =B16*0.055 -> 0 | C34: =C16*0.055 -> 0 | D34: =D16*0.055 -> 0
