Workbook

Sheet Input
A1: Proiezione pensione autonomi — Parametri
A2: Compila le celle BLU. Le celle NERE sono calcolate, le VERDI sono richiami. Pensato per Gestione Separata o cassa professionale; nessun TFR.
A4: Dati anagrafici
A5: Età attuale | B5: 37 | C5: anni compiuti
A6: Età prevista di pensionamento | B6: 67 | C6: es. 67
A7: Anni alla pensione | B7: =Input!$B$6-Input!$B$5 -> 30 | C7: calcolato
A9: Previdenza obbligatoria
A10: (1 = Gestione Separata INPS, 2 = Cassa professionale)
A11: Tipo di previdenza | B11: 1 | C11: informativo; imposta tu l'aliquota sotto
A12: Aliquota contributiva (montante) | B12: 0.2607 | C12: GS 26,07%; cassa: aliquota soggettiva (es. Inarcassa 14,5%, Forense 17%)
A13: Montante previdenziale già accumulato | B13: 25000 | C13: stima del montante contributivo a oggi
A14: Rivalutazione annua del montante (reale) | B14: 0.005 | C14: Gestione Separata: PIL reale ~0,5%, come i dipendenti; cassa: regola propria al netto dell'inflazione
A15: Decadimento coefficiente / biennio | B15: 0.018 | C15: il coefficiente cala ~1,8%/biennio; 0 = congelato
A17: Reddito professionale
A18: (1 = forfettario, 2 = ordinario)
A19: Regime fiscale | B19: 1 | C19: forfettario o ordinario
A20: Coefficiente di redditività (forfettario) | B20: 0.78 | C20: tech/consulenza 78%; usato solo in forfettario
A21: Fatturato / ricavi annui | B21: 40000 | C21: ricavi incassati nell'anno
A22: Costi attività (solo ordinario) | B22: 0 | C22: spese deducibili; ignorato in forfettario
A23: Reddito lordo professionale | B23: =IF(Input!$B$19=1,Input!$B$21*Input!$B$20,Input!$B$21-Input!$B$22) -> 31200 | C23: forfettario: fatturato×coeff; ordinario: fatturato−costi
A24: Crescita reddito annua (reale) | B24: 0.01 | C24: in termini reali, al netto inflazione
A26: Fondo pensione complementare (3° pilastro)
A28: Versamento annuo al fondo pensione | B28: 0 | C28: volontario; vedi nota deducibilità nel foglio Fiscalità
A29: Rendimento annuo atteso del fondo | B29: 0.03 | C29: comparto scelto (reale)
A30: Costo annuo (ISC) del fondo | B30: 0.01 | C30: negoziale 0,2-0,5%; aperto 0,8-1,5%; PIP 1,5-3%
A31: Montante fondo già accumulato | B31: 0 | C31: se hai già un fondo pensione; per la tassa in uscita è trattato come dedotto (stima prudente)
A32: Anni di iscrizione al fondo (al pensionamento) | B32: 5 | C32: per l'aliquota finale 15→9%
A35: Fiscalità
A36: Aliquota sostitutiva (forfettario) | B36: 0.15 | C36: 15% a regime, 5% nei primi 5 anni
A37: Aliquota IRPEF marginale (ordinario) | B37: =IF(Input!$B$23<=28000,0.23,IF(Input!$B$23<=50000,0.33,0.43)) -> 0.33 | C37: 23/33/43% sul reddito lordo
A38: Aliquota fondo pensione finale | B38: =MAX(0.09,0.15-0.003*MAX(0,Input!$B$32-15)) -> 0.15 | C38: 15% fino al 15° anno, poi −0,3%/anno fino a 9%
A39: Inflazione annua attesa | B39: 0.02 | C39: per riferimento
A41: Coefficiente di trasformazione
A42: Coefficiente attuale (età pensione) | B42: =VLOOKUP(Input!$B$6,Coefficienti!A5:C19,3,FALSE()) -> 0.05608 | C42: dalla tabella 2025-2026
A43: Coefficiente PROIETTATO al pensionamento | B43: =Input!$B$42*(1-Input!$B$15)^(Input!$B$7/2) -> 0.042705157 | C43: ridotto per i bienni mancanti; è quello usato
A45: Fondo pensione: deducibilità e uscita
A46: Versamento dedotto ogni anno | B46: =IF(Input!$B$19=1,MIN(Input!$B$28,Input!$B$48,Input!$B$52),MIN(Input!$B$28,Input!$B$48)) -> 0 | C46: forfettario: solo fino agli altri redditi IRPEF (B52); ordinario: fino al plafond
A47: Non dedotti comunicati al fondo (1 = sì, 0 = no) | B47: 1 | C47: entro il 31/12 dell'anno dopo: così in uscita non sono tassati
A48: Plafond deducibilità fondo pensione | B48: 5300 | C48: art. 8 c. 4 D.Lgs. 252/2005 (€5.164,57 fino al 2025)
A50: Massimale, altri redditi e spese
...

Sheet Coefficienti
A1: Coefficienti di trasformazione — biennio 2025-2026
A2: Fonte: Decreto direttoriale 20 novembre 2024 (Min. Lavoro / MEF) — GU n. 35 del 12/02/2025
A4: Età | B4: Divisore | C4: Coefficiente
A5: 57 | B5: 23.789 | C5: 0.04204
A6: 58 | B6: 23.213 | C6: 0.04308
A7: 59 | B7: 22.631 | C7: 0.04419
A8: 60 | B8: 22.044 | C8: 0.04536
A9: 61 | B9: 21.453 | C9: 0.04661
A10: 62 | B10: 20.857 | C10: 0.04795
A11: 63 | B11: 20.258 | C11: 0.04936
A12: 64 | B12: 19.656 | C12: 0.05088
A13: 65 | B13: 19.049 | C13: 0.0525
A14: 66 | B14: 18.441 | C14: 0.05423
A15: 67 | B15: 17.831 | C15: 0.05608
A16: 68 | B16: 17.218 | C16: 0.05808
... A19: 71 | B19: 15.36 | C19: 0.0651
A22: NOTE:
A23: 1. Valgono per pensioni con decorrenza 2025-2026; i coefficienti calano ~1,5-2,2% per biennio.
A24: 2. Per pensioni future il foglio Input proietta il coefficiente in avanti (decadimento/biennio).
A25: 3. Le casse professionali possono usare coefficienti propri: in tal caso sostituire il valore
A26: 'Coefficiente proiettato' nel foglio Input con quello fornito dalla cassa.

Sheet Previdenza
A1: Proiezione previdenza obbligatoria (Gestione Separata / cassa)
A2: Montante contributivo anno per anno, in euro di oggi: contributi fino al massimale, rivalutazione dall'anno dopo il versamento (L. 335/1995). La pensione usa il coefficiente PROIETTATO al pensionamento (foglio Input).
A4: Anno | B4: Età | C4: Reddito | D4: Contributo a montante (fino al massimale) | E4: Montante inizio | F4: Rivalutazione | G4: Montante fine
A5: 0 | B5: =Input!$B$5+A5 -> 37 | C5: =IF(B5<Input!$B$6,Input!$B$23*(1+Input!$B$24)^A5,0) -> 31200 | D5: =MIN(C5,Input!$B$51)*Input!$B$12 -> 8133.84 | E5: =Input!$B$13 -> 25000 | F5: =E5*Input!$B$14 -> 125 | G5: =IF(B5<Input!$B$6,E5+D5+F5,E5) -> 33258.84
A6: 1 | B6: =Input!$B$5+A6 -> 38 | C6: =IF(B6<Input!$B$6,Input!$B$23*(1+Input!$B$24)^A6,0) -> 31512 | D6: =MIN(C6,Input!$B$51)*Input!$B$12 -> 8215.1784 | E6: =G5 -> 33258.84 | F6: =E6*Input!$B$14 -> 166.2942 | G6: =IF(B6<Input!$B$6,E6+D6+F6,E6) -> 41640.313
A7: 2 | B7: =Input!$B$5+A7 -> 39 | C7: =IF(B7<Input!$B$6,Input!$B$23*(1+Input!$B$24)^A7,0) -> 31827.12 | D7: =MIN(C7,Input!$B$51)*Input!$B$12 -> 8297.3302 | E7: =G6 -> 41640.313 | F7: =E7*Input!$B$14 -> 208.20156 | G7: =IF(B7<Input!$B$6,E7+D7+F7,E7) -> 50145.844
A8: 3 | B8: =Input!$B$5+A8 -> 40 | C8: =IF(B8<Input!$B$6,Input!$B$23*(1+Input!$B$24)^A8,0) -> 32145.391 | D8: =MIN(C8,Input!$B$51)*Input!$B$12 -> 8380.3035 | E8: =G7 -> 50145.844 | F8: =E8*Input!$B$14 -> 250.72922 | G8: =IF(B8<Input!$B$6,E8+D8+F8,E8) -> 58776.877
A9: 4 | B9: =Input!$B$5+A9 -> 41 | C9: =IF(B9<Input!$B$6,Input!$B$23*(1+Input!$B$24)^A9,0) -> 32466.845 | D9: =MIN(C9,Input!$B$51)*Input!$B$12 -> 8464.1065 | E9: =G8 -> 58776.877 | F9: =E9*Input!$B$14 -> 293.88439 | G9: =IF(B9<Input!$B$6,E9+D9+F9,E9) -> 67534.868
A10: 5 | B10: =Input!$B$5+A10 -> 42 | C10: =IF(B10<Input!$B$6,Input!$B$23*(1+Input!$B$24)^A10,0) -> 32791.514 | D10: =MIN(C10,Input!$B$51)*Input!$B$12 -> 8548.7476 | E10: =G9 -> 67534.868 | F10: =E10*Input!$B$14 -> 337.67434 | G10: =IF(B10<Input!$B$6,E10+D10+F10,E10) -> 76421.29
A11: 6 | B11: =Input!$B$5+A11 -> 43 | C11: =IF(B11<Input!$B$6,Input!$B$23*(1+Input!$B$24)^A11,0) -> 33119.429 | D11: =MIN(C11,Input!$B$51)*Input!$B$12 -> 8634.2351 | E11: =G10 -> 76421.29 | F11: =E11*Input!$B$14 -> 382.10645 | G11: =IF(B11<Input!$B$6,E11+D11+F11,E11) -> 85437.631
A12: 7 | B12: =Input!$B$5+A12 -> 44 | C12: =IF(B12<Input!$B$6,Input!$B$23*(1+Input!$B$24)^A12,0) -> 33450.623 | D12: =MIN(C12,Input!$B$51)*Input!$B$12 -> 8720.5774 | E12: =G11 -> 85437.631 | F12: =E12*Input!$B$14 -> 427.18816 | G12: =IF(B12<Input!$B$6,E12+D12+F12,E12) -> 94585.397
A13: 8 | B13: =Input!$B$5+A13 -> 45 | C13: =IF(B13<Input!$B$6,Input!$B$23*(1+Input!$B$24)^A13,0) -> 33785.129 | D13: =MIN(C13,Input!$B$51)*Input!$B$12 -> 8807.7832 | E13: =G12 -> 94585.397 | F13: =E13*Input!$B$14 -> 472.92698 | G13: =IF(B13<Input!$B$6,E13+D13+F13,E13) -> 103866.11
A14: 9 | B14: =Input!$B$5+A14 -> 46 | C14: =IF(B14<Input!$B$6,Input!$B$23*(1+Input!$B$24)^A14,0) -> 34122.981 | D14: =MIN(C14,Input!$B$51)*Input!$B$12 -> 8895.861 | E14: =G13 -> 103866.11 | F14: =E14*Input!$B$14 -> 519.33054 | G14: =IF(B14<Input!$B$6,E14+D14+F14,E14) -> 113281.3
A15: 10 | B15: =Input!$B$5+A15 -> 47 | C15: =IF(B15<Input!$B$6,Input!$B$23*(1+Input!$B$24)^A15,0) -> 34464.21 | D15: =MIN(C15,Input!$B$51)*Input!$B$12 -> 8984.8196 | E15: =G14 -> 113281.3 | F15: =E15*Input!$B$14 -> 566.40649 | G15: =IF(B15<Input!$B$6,E15+D15+F15,E15) -> 122832.52
A16: 11 | B16: =Input!$B$5+A16 -> 48 | C16: =IF(B16<Input!$B$6,Input!$B$23*(1+Input!$B$24)^A16,0) -> 34808.852 | D16: =MIN(C16,Input!$B$51)*Input!$B$12 -> 9074.6678 | E16: =G15 -> 122832.52 | F16: =E16*Input!$B$14 -> 614.16262 | G16: =IF(B16<Input!$B$6,E16+D16+F16,E16) -> 132521.36
A17: 12 | B17: =Input!$B$5+A17 -> 49 | C17: =IF(B17<Input!$B$6,Input!$B$23*(1+Input!$B$24)^A17,0) -> 35156.941 | D17: =MIN(C17,Input!$B$51)*Input!$B$12 -> 9165.4145 | E17: =G16 -> 132521.36 | F17: =E17*Input!$B$14 -> 662.60678 | G17: =IF(B17<Input!$B$6,E17+D17+F17,E17) -> 142349.38
... A54: 49 | B54: =Input!$B$5+A54 -> 86 | C54: =IF(B54<Input!$B$6,Input!$B$23*(1+Input!$B$24)^A54,0) -> 0 | D54: =MIN(C54,Input!$B$51)*Input!$B$12 -> 0 | E54: =G53 -> 332344 | F54: =E54*Input!$B$14 -> 1661.72 | G54: =IF(B54<Input!$B$6,E54+D54+F54,E54) -> 332344
A57: RISULTATI A PENSIONAMENTO
A58: Montante finale al pensionamento | B58: =INDEX(G5:G54,MATCH(Input!$B$6-1,B5:B54,0)) -> 332344
A59: Coefficiente proiettato (usato) | B59: =Input!$B$43 -> 0.042705157
A60: Pensione obbligatoria lorda annua | B60: =B58*B59 -> 14192.803
A61: Pensione obbligatoria lorda mensile (×13) | B61: =B60/13 -> 1091.754
A62: Reddito professionale all'ultimo anno | B62: =Input!$B$23*(1+Input!$B$24)^(Input!$B$7-1) -> 41636.521
A63: Tasso di sostituzione lordo | B63: =IF(B62>0,B60/B62,0) -> 0.34087388
A64: IRPEF lorda sulla pensione (scaglioni 2026) | B64: =IF(B60<=28000,B60*0.23,IF(B60<=50000,6440+(B60-28000)*0.33,13700+(B60-50000)*0.43)) -> 3264.3446
A65: Detrazione pensionati (art. 13 c. 3 TUIR) | B65: =IF(B60<=8500,1955,IF(B60<=28000,700+1255*(28000-B60)/19500,IF(B60<=50000,700*(50000-B60)/22000,0))) -> 1588.6171
A66: Addizionali regionali + comunali (~2%, se c'è IRPEF) | B66: =IF(B64-B65>0,B60*0.02,0) -> 283.85605
A67: Pensione obbligatoria NETTA annua | B67: =B60-MAX(0,B64-B65)-B66 -> 12233.219
A68: Pensione obbligatoria NETTA mensile (×13) | B68: =B67/13 -> 941.01684

Sheet Fiscalità
A1: Fiscalità annua — forfettario vs ordinario
A2: Fotografia dell'anno corrente nei due regimi. Mostra dove e quanto è deducibile il contributo previdenziale e il versamento al fondo pensione.
A4: Voce | B4: Forfettario | C4: Ordinario
A5: Fatturato / ricavi | B5: =Input!$B$21 -> 40000 | C5: =Input!$B$21 -> 40000
A6: Reddito lordo professionale | B6: =Input!$B$21*Input!$B$20 -> 31200 | C6: =Input!$B$21-Input!$B$22 -> 40000 | D6: forf.: ×coeff; ord.: −costi
A7: − Contributi previdenziali obbligatori | B7: =B6*Input!$B$12 -> 8133.84 | C7: =MIN(C6,Input!$B$51)*Input!$B$12 -> 10428 | D7: DEDUCIBILI in entrambi i regimi
A8: − Versamento fondo pensione dedotto | B8: =MIN(Input!$B$28,Input!$B$48,Input!$B$52) -> 0 | C8: =MIN(Input!$B$28,Input!$B$48) -> 0 | D8: forf.: solo dagli altri redditi IRPEF; ord.: dal reddito complessivo
A9: Imponibile (forf.: sostitutiva; ord.: IRPEF con altri redditi) | B9: =MAX(0,B6-B7) -> 23066.16 | C9: =MAX(0,C6-C7+Input!$B$52-C8) -> 29572
A10: Imposta | B10: =B9*Input!$B$36+IF(MAX(0,Input!$B$52-B8)<=28000,MAX(0,Input!$B$52-B8)*0.23,IF(MAX(0,Input!$B$52-B8)<=50000,6440+(MAX(0,Input!$B$52-B8)-28000)*0.33,13700+(MAX(0,Input!$B$52-B8)-50000)*0.43)) -> 3459.924 | C10: =IF(C9<=28000,C9*0.23,IF(C9<=50000,6440+(C9-28000)*0.33,13700+(C9-50000)*0.43)) -> 6958.76 | D10: forf.: sostitutiva + IRPEF lorda sugli altri redditi; ord.: IRPEF lorda (ante detrazioni)
A11: Netto disponibile (redditi − contributi − imposte) | B11: =B6-B7+Input!$B$52-B10 -> 19606.236 | C11: =C6-C7+Input!$B$52-C10 -> 22613.24
A13: Beneficio fiscale del versamento al fondo pensione
A14: Imposta SENZA fondo pensione | B14: =B9*Input!$B$36+IF(Input!$B$52<=28000,Input!$B$52*0.23,IF(Input!$B$52<=50000,6440+(Input!$B$52-28000)*0.33,13700+(Input!$B$52-50000)*0.43)) -> 3459.924 | C14: =IF(MAX(0,C6-C7+Input!$B$52)<=28000,MAX(0,C6-C7+Input!$B$52)*0.23,IF(MAX(0,C6-C7+Input!$B$52)<=50000,6440+(MAX(0,C6-C7+Input!$B$52)-28000)*0.33,13700+(MAX(0,C6-C7+Input!$B$52)-50000)*0.43)) -> 6958.76
A15: Risparmio fiscale dal fondo pensione | B15: =B14-B10 -> 0 | C15: =C14-C10 -> 0 | D15: forf.: IRPEF risparmiata sugli altri redditi; ord.: aliquota × versamento
A17: LETTURA: i contributi previdenziali OBBLIGATORI (Gestione Separata o cassa) si deducono in entrambi
A18: i regimi e abbattono l'imponibile. Il versamento VOLONTARIO al fondo pensione complementare invece
A19: si deduce solo contro l'IRPEF: in ORDINARIO fino al plafond, in forfettario solo fino agli altri redditi
A20: IRPEF (Input B52). Per un forfettario puro il risparmio in ingresso è zero (riga evidenziata). Il fondo
A21: pensione resta utile al forfettario per la capitalizzazione e perché i versamenti non dedotti, se
A22: comunicati al fondo, in uscita non sono tassati; va confrontato con un PAC di ETF (più liquido). L'IRPEF è
A23: lorda, ante detrazioni: l'imposta ordinaria reale è un po' più bassa. Confronto indicativo.

Sheet Complementare
A1: Fondo pensione complementare (3° pilastro)
A2: Accumulo del fondo pensione anno per anno (rendimento netto dell'ISC). La rendita finale si somma alla pensione obbligatoria nel Riepilogo.
A4: Anno | B4: Età | C4: Versamento | D4: Montante inizio | E4: Rendimento netto | F4: Montante fine | G4: Base tassabile in uscita (€ oggi)
A5: 0 | B5: =Input!$B$5+A5 -> 37 | C5: =IF(B5<Input!$B$6,Input!$B$28,0) -> 0 | D5: =Input!$B$31 -> 0 | E5: =(D5+C5)*(Input!$B$29-Input!$B$30) -> 0 | F5: =IF(B5<Input!$B$6,D5+C5+E5,D5) -> 0 | G5: =IF(B5<Input!$B$6,(Input!$B$46+IF(Input!$B$47=1,0,C5-Input!$B$46))*(1+Input!$B$39)^(A5-Input!$B$7),0) -> 0
A6: 1 | B6: =Input!$B$5+A6 -> 38 | C6: =IF(B6<Input!$B$6,Input!$B$28,0) -> 0 | D6: =F5 -> 0 | E6: =(D6+C6)*(Input!$B$29-Input!$B$30) -> 0 | F6: =IF(B6<Input!$B$6,D6+C6+E6,D6) -> 0 | G6: =IF(B6<Input!$B$6,(Input!$B$46+IF(Input!$B$47=1,0,C6-Input!$B$46))*(1+Input!$B$39)^(A6-Input!$B$7),0) -> 0
A7: 2 | B7: =Input!$B$5+A7 -> 39 | C7: =IF(B7<Input!$B$6,Input!$B$28,0) -> 0 | D7: =F6 -> 0 | E7: =(D7+C7)*(Input!$B$29-Input!$B$30) -> 0 | F7: =IF(B7<Input!$B$6,D7+C7+E7,D7) -> 0 | G7: =IF(B7<Input!$B$6,(Input!$B$46+IF(Input!$B$47=1,0,C7-Input!$B$46))*(1+Input!$B$39)^(A7-Input!$B$7),0) -> 0
A8: 3 | B8: =Input!$B$5+A8 -> 40 | C8: =IF(B8<Input!$B$6,Input!$B$28,0) -> 0 | D8: =F7 -> 0 | E8: =(D8+C8)*(Input!$B$29-Input!$B$30) -> 0 | F8: =IF(B8<Input!$B$6,D8+C8+E8,D8) -> 0 | G8: =IF(B8<Input!$B$6,(Input!$B$46+IF(Input!$B$47=1,0,C8-Input!$B$46))*(1+Input!$B$39)^(A8-Input!$B$7),0) -> 0
A9: 4 | B9: =Input!$B$5+A9 -> 41 | C9: =IF(B9<Input!$B$6,Input!$B$28,0) -> 0 | D9: =F8 -> 0 | E9: =(D9+C9)*(Input!$B$29-Input!$B$30) -> 0 | F9: =IF(B9<Input!$B$6,D9+C9+E9,D9) -> 0 | G9: =IF(B9<Input!$B$6,(Input!$B$46+IF(Input!$B$47=1,0,C9-Input!$B$46))*(1+Input!$B$39)^(A9-Input!$B$7),0) -> 0
A10: 5 | B10: =Input!$B$5+A10 -> 42 | C10: =IF(B10<Input!$B$6,Input!$B$28,0) -> 0 | D10: =F9 -> 0 | E10: =(D10+C10)*(Input!$B$29-Input!$B$30) -> 0 | F10: =IF(B10<Input!$B$6,D10+C10+E10,D10) -> 0 | G10: =IF(B10<Input!$B$6,(Input!$B$46+IF(Input!$B$47=1,0,C10-Input!$B$46))*(1+Input!$B$39)^(A10-Input!$B$7),0) -> 0
A11: 6 | B11: =Input!$B$5+A11 -> 43 | C11: =IF(B11<Input!$B$6,Input!$B$28,0) -> 0 | D11: =F10 -> 0 | E11: =(D11+C11)*(Input!$B$29-Input!$B$30) -> 0 | F11: =IF(B11<Input!$B$6,D11+C11+E11,D11) -> 0 | G11: =IF(B11<Input!$B$6,(Input!$B$46+IF(Input!$B$47=1,0,C11-Input!$B$46))*(1+Input!$B$39)^(A11-Input!$B$7),0) -> 0
A12: 7 | B12: =Input!$B$5+A12 -> 44 | C12: =IF(B12<Input!$B$6,Input!$B$28,0) -> 0 | D12: =F11 -> 0 | E12: =(D12+C12)*(Input!$B$29-Input!$B$30) -> 0 | F12: =IF(B12<Input!$B$6,D12+C12+E12,D12) -> 0 | G12: =IF(B12<Input!$B$6,(Input!$B$46+IF(Input!$B$47=1,0,C12-Input!$B$46))*(1+Input!$B$39)^(A12-Input!$B$7),0) -> 0
A13: 8 | B13: =Input!$B$5+A13 -> 45 | C13: =IF(B13<Input!$B$6,Input!$B$28,0) -> 0 | D13: =F12 -> 0 | E13: =(D13+C13)*(Input!$B$29-Input!$B$30) -> 0 | F13: =IF(B13<Input!$B$6,D13+C13+E13,D13) -> 0 | G13: =IF(B13<Input!$B$6,(Input!$B$46+IF(Input!$B$47=1,0,C13-Input!$B$46))*(1+Input!$B$39)^(A13-Input!$B$7),0) -> 0
A14: 9 | B14: =Input!$B$5+A14 -> 46 | C14: =IF(B14<Input!$B$6,Input!$B$28,0) -> 0 | D14: =F13 -> 0 | E14: =(D14+C14)*(Input!$B$29-Input!$B$30) -> 0 | F14: =IF(B14<Input!$B$6,D14+C14+E14,D14) -> 0 | G14: =IF(B14<Input!$B$6,(Input!$B$46+IF(Input!$B$47=1,0,C14-Input!$B$46))*(1+Input!$B$39)^(A14-Input!$B$7),0) -> 0
A15: 10 | B15: =Input!$B$5+A15 -> 47 | C15: =IF(B15<Input!$B$6,Input!$B$28,0) -> 0 | D15: =F14 -> 0 | E15: =(D15+C15)*(Input!$B$29-Input!$B$30) -> 0 | F15: =IF(B15<Input!$B$6,D15+C15+E15,D15) -> 0 | G15: =IF(B15<Input!$B$6,(Input!$B$46+IF(Input!$B$47=1,0,C15-Input!$B$46))*(1+Input!$B$39)^(A15-Input!$B$7),0) -> 0
A16: 11 | B16: =Input!$B$5+A16 -> 48 | C16: =IF(B16<Input!$B$6,Input!$B$28,0) -> 0 | D16: =F15 -> 0 | E16: =(D16+C16)*(Input!$B$29-Input!$B$30) -> 0 | F16: =IF(B16<Input!$B$6,D16+C16+E16,D16) -> 0 | G16: =IF(B16<Input!$B$6,(Input!$B$46+IF(Input!$B$47=1,0,C16-Input!$B$46))*(1+Input!$B$39)^(A16-Input!$B$7),0) -> 0
A17: 12 | B17: =Input!$B$5+A17 -> 49 | C17: =IF(B17<Input!$B$6,Input!$B$28,0) -> 0 | D17: =F16 -> 0 | E17: =(D17+C17)*(Input!$B$29-Input!$B$30) -> 0 | F17: =IF(B17<Input!$B$6,D17+C17+E17,D17) -> 0 | G17: =IF(B17<Input!$B$6,(Input!$B$46+IF(Input!$B$47=1,0,C17-Input!$B$46))*(1+Input!$B$39)^(A17-Input!$B$7),0) -> 0
... A54: 49 | B54: =Input!$B$5+A54 -> 86 | C54: =IF(B54<Input!$B$6,Input!$B$28,0) -> 0 | D54: =F53 -> 0 | E54: =(D54+C54)*(Input!$B$29-Input!$B$30) -> 0 | F54: =IF(B54<Input!$B$6,D54+C54+E54,D54) -> 0 | G54: =IF(B54<Input!$B$6,(Input!$B$46+IF(Input!$B$47=1,0,C54-Input!$B$46))*(1+Input!$B$39)^(A54-Input!$B$7),0) -> 0
A57: RISULTATI FONDO PENSIONE
A58: Montante fondo al pensionamento | B58: =INDEX(F5:F54,MATCH(Input!$B$6-1,B5:B54,0)) -> 0
A59: Totale versato (somma versamenti) | B59: =Input!$B$31+SUMIF(B5:B54,"<"&Input!$B$6,C5:C54) -> 0
A60: Tassa finale (15→9%) sui versamenti dedotti | B60: =(Input!$B$31*(1+Input!$B$39)^(-Input!$B$7)+SUM(G5:G54))*Input!$B$38 -> 0
A61: Montante netto disponibile | B61: =B58-B60 -> 0
A62: Rendita annua stimata (× coeff.) | B62: =B61*Input!$B$43 -> 0
A64: NOTA DEDUCIBILITÀ: in regime ORDINARIO i versamenti sono deducibili dall'IRPEF fino a €5.300/anno
A65: (vedi foglio Fiscalità). In FORFETTARIO puro non sono deducibili, ma se comunicati al fondo entro il 31/12
A66: dell'anno dopo in uscita non sono tassati: il fondo rende per capitalizzazione e uscita esente su quella parte.
A67: Tassa finale solo sui versamenti dedotti (e sui non dedotti NON comunicati); rendimenti già tassati esclusi (art. 11 c. 6).

Sheet Riepilogo
A1: Riepilogo: pensione attesa e gap
A2: Previdenza obbligatoria e complementare, tasso di sostituzione, gap rispetto al reddito attuale e alla spesa target. Valori in euro di oggi (reali).
A4: Pensione attesa (annua, lorda)
A5: Previdenza obbligatoria | B5: =Previdenza!B60 -> 14192.803
A6: Fondo pensione complementare | B6: =Complementare!B62 -> 0
A7: Pensione totale annua | B7: =B5+B6 -> 14192.803
A8: Pensione totale mensile (×13) | B8: =B7/13 -> 1091.754
A9: Pensione totale NETTA annua | B9: =Previdenza!B67+Complementare!B62 -> 12233.219
A10: Tasso di sostituzione e gap
A11: Reddito professionale finale (annuo) | B11: =Previdenza!B62 -> 41636.521
A12: Tasso di sostituzione — solo obbligatoria | B12: =IF(B11>0,B5/B11,0) -> 0.34087388
A13: Tasso di sostituzione — totale | B13: =IF(B11>0,B7/B11,0) -> 0.34087388
A14: Gap annuo (reddito finale − pensione totale) | B14: =MAX(0,B11-B7) -> 27443.718 | C14: quanto manca per mantenere il reddito
A15: Gap mensile (×13) | B15: =B14/13 -> 2111.0553
A17: Obbligatoria e complementare (lorde)
A18: Tasso di sostituzione obbligatoria + complementare
A19: Scenario | B19: Pensione annua | C19: Tasso sost.
A20: Solo previdenza obbligatoria | B20: =B5 -> 14192.803 | C20: =IF(B11>0,B5/B11,0) -> 0.34087388
A21: Obbligatoria + fondo pensione attuale | B21: =B7 -> 14192.803 | C21: =IF(B11>0,B7/B11,0) -> 0.34087388
A23: Il tasso di sostituzione degli autonomi è strutturalmente più basso di quello dei dipendenti,
A24: perché l'aliquota contributiva è minore (26,07% in Gestione Separata, o l'aliquota soggettiva
A25: della cassa, contro il 33% del dipendente). Il fondo pensione complementare serve a colmare il gap,
A26: ma per un forfettario puro va valutato senza il vantaggio della deduzione in ingresso (foglio Fiscalità).
A27: Valori reali (euro di oggi); proiezione indicativa, non una garanzia. Non è consulenza.
A29: Scenari: gap rispetto alla spesa target (€ di oggi)
A30: Come proiezione-tenore-vita.md: gap = spesa target − pensione netta. Base = fogli di calcolo; le altre colonne ricalcolano con i propri parametri.
A31: Voce | B31: Conservativo | C31: Base | D31: Ottimistico
A32: Crescita reddito annua (reale) | B32: =Input!$B$24-0.01 -> 0 | C32: =Input!$B$24 -> 0.01 | D32: =Input!$B$24+0.01 -> 0.02
A33: Rivalutazione montante (reale) | B33: =Input!$B$14-0.005 -> 0 | C33: =Input!$B$14 -> 0.005 | D33: =Input!$B$14+0.005 -> 0.01
A34: Decadimento coefficiente / biennio | B34: 0.022 | C34: =Input!$B$15 -> 0.018 | D34: 0.015
A35: Rendimento netto fondo (reale) | B35: =Input!$B$29-Input!$B$30-0.01 -> 0.01 | C35: =Input!$B$29-Input!$B$30 -> 0.02 | D35: =Input!$B$29-Input!$B$30+0.01 -> 0.03
A36: Pensione obbligatoria lorda | B36: =(Input!$B$13*(1+B33)^Input!$B$7+SUMPRODUCT((Previdenza!$A$5:$A$54<Input!$B$7)*((Input!$B$23*(1+B32)^Previdenza!$A$5:$A$54+Input!$B$51-ABS(Input!$B$23*(1+B32)^Previdenza!$A$5:$A$54-Input!$B$51))/2)*Input!$B$12*(1+B33)^(Input!$B$7-1-Previdenza!$A$5:$A$54)))*Input!$B$42*(1-B34)^(Input!$B$7/2) -> 10806.067 | C36: =(Input!$B$13*(1+C33)^Input!$B$7+SUMPRODUCT((Previdenza!$A$5:$A$54<Input!$B$7)*((Input!$B$23*(1+C32)^Previdenza!$A$5:$A$54+Input!$B$51-ABS(Input!$B$23*(1+C32)^Previdenza!$A$5:$A$54-Input!$B$51))/2)*Input!$B$12*(1+C33)^(Input!$B$7-1-Previdenza!$A$5:$A$54)))*Input!$B$42*(1-C34)^(Input!$B$7/2) -> 14192.803 | D36: =(Input!$B$13*(1+D33)^Input!$B$7+SUMPRODUCT((Previdenza!$A$5:$A$54<Input!$B$7)*((Input!$B$23*(1+D32)^Previdenza!$A$5:$A$54+Input!$B$51-ABS(Input!$B$23*(1+D32)^Previdenza!$A$5:$A$54-Input!$B$51))/2)*Input!$B$12*(1+D33)^(Input!$B$7-1-Previdenza!$A$5:$A$54)))*Input!$B$42*(1-D34)^(Input!$B$7/2) -> 18360.595
A37: Pensione obbligatoria netta | B37: =B36-MAX(0,IF(B36<=28000,B36*0.23,IF(B36<=50000,6440+(B36-28000)*0.33,13700+(B36-50000)*0.43))-IF(B36<=8500,1955,IF(B36<=28000,700+1255*(28000-B36)/19500,IF(B36<=50000,700*(50000-B36)/22000,0))))-IF(IF(B36<=28000,B36*0.23,IF(B36<=50000,6440+(B36-28000)*0.33,13700+(B36-50000)*0.43))-IF(B36<=8500,1955,IF(B36<=28000,700+1255*(28000-B36)/19500,IF(B36<=50000,700*(50000-B36)/22000,0)))>0,B36*0.02,0) -> 9911.134 | C37: =C36-MAX(0,IF(C36<=28000,C36*0.23,IF(C36<=50000,6440+(C36-28000)*0.33,13700+(C36-50000)*0.43))-IF(C36<=8500,1955,IF(C36<=28000,700+1255*(28000-C36)/19500,IF(C36<=50000,700*(50000-C36)/22000,0))))-IF(IF(C36<=28000,C36*0.23,IF(C36<=50000,6440+(C36-28000)*0.33,13700+(C36-50000)*0.43))-IF(C36<=8500,1955,IF(C36<=28000,700+1255*(28000-C36)/19500,IF(C36<=50000,700*(50000-C36)/22000,0)))>0,C36*0.02,0) -> 12233.219 | D37: =D36-MAX(0,IF(D36<=28000,D36*0.23,IF(D36<=50000,6440+(D36-28000)*0.33,13700+(D36-50000)*0.43))-IF(D36<=8500,1955,IF(D36<=28000,700+1255*(28000-D36)/19500,IF(D36<=50000,700*(50000-D36)/22000,0))))-IF(IF(D36<=28000,D36*0.23,IF(D36<=50000,6440+(D36-28000)*0.33,13700+(D36-50000)*0.43))-IF(D36<=8500,1955,IF(D36<=28000,700+1255*(28000-D36)/19500,IF(D36<=50000,700*(50000-D36)/22000,0)))>0,D36*0.02,0) -> 15090.828
A38: Rendita fondo (netta della tassa in uscita) | B38: =((Input!$B$31*(1+B35)^Input!$B$7+Input!$B$28*SUMPRODUCT((Complementare!$A$5:$A$54<Input!$B$7)*(1+B35)^(Input!$B$7-Complementare!$A$5:$A$54)))-((Input!$B$31*(1+Input!$B$39)^(-Input!$B$7)+(Input!$B$46+IF(Input!$B$47=1,0,Input!$B$28-Input!$B$46))*SUMPRODUCT((Complementare!$A$5:$A$54<Input!$B$7)*(1+Input!$B$39)^(Complementare!$A$5:$A$54-Input!$B$7)))*Input!$B$38))*Input!$B$42*(1-B34)^(Input!$B$7/2) -> 0 | C38: =((Input!$B$31*(1+C35)^Input!$B$7+Input!$B$28*SUMPRODUCT((Complementare!$A$5:$A$54<Input!$B$7)*(1+C35)^(Input!$B$7-Complementare!$A$5:$A$54)))-((Input!$B$31*(1+Input!$B$39)^(-Input!$B$7)+(Input!$B$46+IF(Input!$B$47=1,0,Input!$B$28-Input!$B$46))*SUMPRODUCT((Complementare!$A$5:$A$54<Input!$B$7)*(1+Input!$B$39)^(Complementare!$A$5:$A$54-Input!$B$7)))*Input!$B$38))*Input!$B$42*(1-C34)^(Input!$B$7/2) -> 0 | D38: =((Input!$B$31*(1+D35)^Input!$B$7+Input!$B$28*SUMPRODUCT((Complementare!$A$5:$A$54<Input!$B$7)*(1+D35)^(Input!$B$7-Complementare!$A$5:$A$54)))-((Input!$B$31*(1+Input!$B$39)^(-Input!$B$7)+(Input!$B$46+IF(Input!$B$47=1,0,Input!$B$28-Input!$B$46))*SUMPRODUCT((Complementare!$A$5:$A$54<Input!$B$7)*(1+Input!$B$39)^(Complementare!$A$5:$A$54-Input!$B$7)))*Input!$B$38))*Input!$B$42*(1-D34)^(Input!$B$7/2) -> 0
A39: Pensione totale netta | B39: =B37+B38 -> 9911.134 | C39: =C37+C38 -> 12233.219 | D39: =D37+D38 -> 15090.828
A40: Spesa target annua (€ di oggi) | B40: =Input!$B$55 -> 18720 | C40: =Input!$B$55 -> 18720 | D40: =Input!$B$55 -> 18720
A41: GAP (spesa target − pensione netta) | B41: =B40-B39 -> 8808.866 | C41: =C40-C39 -> 6486.7811 | D41: =D40-D39 -> 3629.1715
A42: Gap % della spesa target | B42: =IFERROR(B41/B40,0) -> 0.47055908 | C42: =IFERROR(C41/C40,0) -> 0.34651608 | D42: =IFERROR(D41/D40,0) -> 0.193866
A44: Scenari indicativi in euro di oggi; per le casse la rivalutazione segue la regola della cassa. Non è consulenza.
